<!DOCTYPE html>
<html>
	<head>
		<meta charset="UTF-8">
		<title></title>
	</head>
	<body>
	</body>
</html>
<script type="text/javascript">
/*	Promise对象有以下两个特点。

（1）对象的状态不受外界影响。Promise对象代表一个异步操作，有三种状态：pending（进行中）、fulfilled（已成功）和rejected（已失败）。只有异步操作的结果，可以决定当前是哪一种状态，
任何其他操作都无法改变这个状态。这也是Promise这个名字的由来，它的英语意思就是“承诺”，表示其他手段无法改变。

（2）一旦状态改变，就不会再变，任何时候都可以得到这个结果。Promise对象的状态改变，只有两种可能：从pending变为fulfilled和从pending变为rejected。只要这两种情况发生，状态就凝固了，
不会再变了，会一直保持这个结果，这时就称为 resolved（已定型）。如果改变已经发生了，你再对Promise对象添加回调函数，
也会立即得到这个结果。这与事件（Event）完全不同，事件的特点是，如果你错过了它，再去监听，是得不到结果的。

注意，为了行文方便，本章后面的resolved统一只指fulfilled状态，不包含rejected状态。

有了Promise对象，就可以将异步操作以同步操作的流程表达出来，避免了层层嵌套的回调函数。此外，Promise对象提供统一的接口，使得控制异步操作更加容易。

Promise也有一些缺点。首先，无法取消Promise，一旦新建它就会立即执行，无法中途取消。其次，如果不设置回调函数，Promise内部抛出的错误，不会反应到外部。
第三，当处于pending状态时，无法得知目前进展到哪一个阶段（刚刚开始还是即将完成）。

如果某些事件不断地反复发生，一般来说，使用 Stream 模式是比部署Promise更好的选择。*/


/*Promise构造函数接受一个函数作为参数，该函数的两个参数分别是resolve和reject。它们是两个函数，由 JavaScript 引擎提供，不用自己部署。

resolve函数的作用是，将Promise对象的状态从“未完成”变为“成功”（即从 pending 变为 resolved），在异步操作成功时调用，并将异步操作的结果，
作为参数传递出去；reject函数的作用是，
将Promise对象的状态从“未完成”变为“失败”（即从 pending 变为 rejected），在异步操作失败时调用，并将异步操作报出的错误，作为参数传递出去。*/
//const promise=new Promise(function(resolve,reject){
//	if (/*异步成功*/) {
//		resolve(value);
//	} else{
//		reject(value)
//	}
//})


/*then方法可以接受两个回调函数作为参数。第一个回调函数是Promise对象的状态变为resolved时调用，
第二个回调函数是Promise对象的状态变为rejected时调用。其中，第二个函数是可选的，不一定要提供。
这两个函数都接受Promise对象传出的值作为参数。*/

//promise.then(function(value){
//	//success
//},function(error){
//	//failure
//})


//timeout方法返回一个Promise实例，表示一段时间以后才会发生的结果。
//过了指定的时间（ms参数）以后，Promise实例的状态变为resolved，就会触发then方法绑定的回调函数。


function timeout(ms){
	return new Promise((resolve,reject)=>{
		setTimeout(resolve,ms,"done");//done是传的值
	})
}

timeout(100).then(value=>{console.log(value)})


//使用Promise包装了一个图片加载的异步操作。如果加载成功，就调用resolve方法，否则就调用reject方法。

function loadImageAsync(url) {
  return new Promise(function(resolve, reject) {
    const image = new Image();

    image.onload = function() {
      resolve(image);
    };

    image.onerror = function() {
      reject(new Error('Could not load image at ' + url));
    };

    image.src = url;
  });
}



//下面是一个用Promise对象实现的 Ajax 操作的例子。

//getJSON是对 XMLHttpRequest 对象的封装，用于发出一个针对 JSON 数据的 HTTP 请求，并且返回一个Promise对象。需要注意的是，
//在getJSON内部，resolve函数和reject函数调用时，都带有参数。
const getJSON = function(url) {
  const promise = new Promise(function(resolve, reject){
    const handler = function() {
      if (this.readyState !== 4) {
        return;
      }
      if (this.status === 200) {
        resolve(this.response);
      } else {
        reject(new Error(this.statusText));
      }
    };
    const client = new XMLHttpRequest();
    client.open("GET", url);
    client.onreadystatechange = handler;
    client.responseType = "json";
    client.setRequestHeader("Accept", "application/json");
    client.send();

  });

  return promise;
};

getJSON("/posts.json").then(function(json) {
  console.log('Contents: ' + json);
}, function(error) {
  console.error('出错了', error);
});




new Promise((resolve, reject) => {
  resolve(1);
  console.log(2);
}).then(r => {
  console.log(r);
});
// 2
// 1
//上面代码中，调用resolve(1)以后，后面的console.log(2)还是会执行，并且会首先打印出来。这是因为立即 resolved 的 Promise 是在本轮事件循环的末尾执行，总是晚于本轮循环的同步任务。
//
//一般来说，调用resolve或reject以后，Promise 的使命就完成了，后继操作应该放到then方法里面，而不应该直接写在resolve或reject的后面。所以，最好在它们前面加上return语句，这样就不会有意外。

new Promise((resolve, reject) => {
  return resolve(1);
  // 后面的语句不会执行
  console.log(2);
})


//getJSON方法返回一个 Promise 对象，如果该对象状态变为resolved，则会调用then方法指定的回调函数；如果异步操作抛出错误，状态就会变为rejected，就会调用catch方法指定的回调函数，处理这个错误。
//另外，then方法指定的回调函数，如果运行中抛出错误，也会被catch方法捕获。
//第一种方法
p.then((val) => console.log('fulfilled:', val))
  .catch((err) => console.log('rejected', err));
 //第二种方法
  const promise = new Promise(function(resolve, reject) {
	  throw new Error('test');
	});
	promise.catch(function(error) {
	  console.log(error);
	});
// 写法一
const promise = new Promise(function(resolve, reject) {
  try {
  	//成功后执行此方法
    throw new Error('test');
  } catch(e) {
  	//出现异常执行这里的方法
    reject(e);
  }
});
promise.catch(function(error) {
  console.log(error);
});
// 写法二
const promise = new Promise(function(resolve, reject) {
  reject(new Error('test'));
});
promise.catch(function(error) {
  console.log(error);
});

//如果 Promise 状态已经变成resolved，再抛出错误是无效的。
//上面代码中，Promise 在resolve语句后面，再抛出错误，不会被捕获，等于没有抛出。
//因为 Promise 的状态一旦改变，就永久保持该状态，不会再变了。
const promise = new Promise(function(resolve, reject) {
  resolve('ok');
  throw new Error('test');
});
promise
  .then(function(value) { console.log(value) })
  .catch(function(error) { console.log(error) });
// ok
</script>